<?xml version="1.0"?>
<sdf version="1.6">
  <model name="qball">
    <static>0</static>

  <gazebo reference="esfera">
		<material>Gazebo/FlatBlack</material>
	</gazebo>

<!-- ***************************** Links *********************************** -->    
  
    <link name="base_frame">
     <pose>0 0 0.8 0 0 0.785</pose>
      	<visual name="visual">
        <geometry>
          <mesh><uri>model://qball/meshes/completo.dae</uri><scale>3.3 3.3 3.3 </scale></mesh>
        </geometry>
      </visual>
   
      <inertial>
        <mass>1</mass>
        <inertia>
          <ixx>0.08666</ixx><ixy>0</ixy><ixz>0</ixz><iyy>0.08666</iyy><iyz>0</iyz><izz>0.16666</izz>
        </inertia>
        <pose>0 0 0.1 0 0 0</pose>
      </inertial>   
    </link>
      
      
   <link name="esfera">
    	<pose>0 0 0.8  0 0 0.785</pose>
    	
    	<inertial>
        <mass>0.001</mass>
        <inertia><ixx>6.97e-4</ixx><ixy>0</ixy><ixz>0</ixz><iyy>6.97e-4</iyy><iyz>0</iyz><izz>6.97e-4</izz></inertia>
        <pose>0 0 0.015 0 0 0</pose>
      </inertial>
      
      <visual name="visual">
        <geometry>
          <mesh><uri>model://qball/meshes/esfera.stl</uri><scale>3.3 3.3 3.3</scale></mesh>
        </geometry>
        <material> 
          <ambient>0.1 0.1 0.1 1</ambient>
          <diffuse>0.1 0.1 0.2 1</diffuse>
          <specular>0 0 0 0</specular>
          <emissive>0 0 0 1</emissive>
        </material>
      </visual>
      
      <collision name="collision">
        <pose>0 0 0.2 0 0 0</pose> <geometry> <sphere>0.2</sphere> </geometry>
      </collision>
      
      <collision name="base esfera">
      	<pose>0 0 -0.7 0 0 -0.785</pose> <geometry><box><size>1.5 1.5 0.2</size></box> </geometry>
      </collision>
    </link>

      
    <link name="prop1">   <!--pose>0.195 0 0.067  0 0 0</pose-->  <!-- Sin la escala -->
    <!--pose>0.6435 0 1.0211  0 0 0</pose--> <!-- Apunta al eje X-->  
    	<pose>0.46 0.46 1.02  0 0 -0.785398</pose> <!-- Normal Vitarana--> 
    	
    	<inertial>
        <mass>0.1</mass>
        <inertia><ixx>0.00001</ixx><ixy>0</ixy><ixz>0</ixz><iyy>0.001</iyy><iyz>0</iyz><izz>0.001</izz></inertia>
        <pose>0 0 0.015 0 0 -1.5708</pose>
      </inertial>
      
      <visual name="visual">
        <geometry>
          <mesh><uri>model://qball/meshes/x.dae</uri><scale>3.3 3.3 3.3</scale></mesh>
        </geometry>
      </visual>
      
      <collision name="collision">
        <pose>0 0 0.015 0 0 -1.5708</pose>
        <geometry>
          <!--box><size>0.696 0.1 0.03</size></box-->
          <box><size>0.696 0.1 0.03</size></box>
        </geometry>
      </collision>
    </link>

    <link name="prop2">  
    	<!--pose>-0.6435 0 1.0211  0 0 0</pose-->
    	<pose>0.46 -0.46 1.02  0 0 0.785398</pose>
    	
    	<inertial>
        <mass>0.1</mass>
        <inertia><ixx>0.00001</ixx><ixy>0</ixy><ixz>0</ixz><iyy>0.001</iyy><iyz>0</iyz><izz>0.001</izz></inertia>
        <pose>0 0 0.015 0 0 1.5708</pose>
      </inertial>
      
      <visual name="visual">
        <geometry>
          <mesh><uri>model://qball/meshes/x.dae</uri><scale>3.3 3.3 3.3</scale></mesh>
        </geometry>
      </visual>
      
      <collision name="collision">
        <pose>0 0 0.015 0 0 1.5708</pose>
        <geometry>
          <box><size>0.696 0.1 0.03</size></box>
        </geometry>
      </collision>
    </link>

    <link name="prop3"> 
     <!--pose> 0 0.6435 1.0211  0 0 0</pose-->
    	<pose>-0.445 -0.46 1.02  0 0 -0.785398</pose>
    	
    	<inertial>
        <mass>0.1</mass>
        <inertia><ixx>0.00001</ixx><ixy>0</ixy><ixz>0</ixz><iyy>0.001</iyy><iyz>0</iyz><izz>0.001</izz></inertia>
        <pose>0 0 0.015 0 0 -1.5708</pose>
      </inertial>
      
      <visual name="visual">
        <geometry>
          <mesh><uri>model://qball/meshes/x.dae</uri><scale>3.3 3.3 3.3</scale></mesh>
        </geometry>
      </visual>
      
      <collision name="collision">
        <pose>0 0 0.015 0 0 -1.5708</pose>
        <geometry>
          <box><size>0.696 0.1 0.03</size></box>
        </geometry>
      </collision>
    </link>

    <link name="prop4">  
     <!--pose>0 -0.6435 1.0211  0 0 0</pose-->
    	<pose>-0.46 0.46 1.02  0 0 0.785398</pose>
    	
    	<inertial>
    		<mass>0.1</mass>
    		<inertia><ixx>0.00001</ixx><ixy>0</ixy><ixz>0</ixz><iyy>0.001</iyy><iyz>0</iyz><izz>0.001</izz></inertia>
        <pose>0 0 0.015 0 0 1.5708</pose>
    	</inertial>
      
      <visual name="visual">
        <geometry>
          <mesh><uri>model://qball/meshes/x.dae</uri><scale>3.3 3.3 3.3</scale></mesh>
        </geometry>
      </visual>
      
      <collision name="collision">
        <pose>0 0 0.015 0 0 1.5708</pose>
        <geometry>
          <box><size>0.696 0.1 0.03</size></box>
        </geometry>
      </collision>
    </link>





<!-- ************************** Joints ******************************** -->

		<joint name="esfera_joint" type="fixed">
      <parent>base_frame</parent>
      <child>esfera</child>
      <pose>0 0 0  0 0 0</pose>
    </joint>
    
    <joint name="prop1_joint" type="revolute">
      <parent>base_frame</parent>
      <child>prop1</child>
      <pose>0 0 0  0 0 0</pose>
      <axis>
        <xyz>0 0 1</xyz>
      </axis>
    </joint>

   	<joint name="prop2_joint" type="revolute">
      <parent>base_frame</parent>
      <child>prop2</child>
      <pose>0 0 0  0 0 0</pose>
      <axis>
        <xyz>0 0 -1</xyz>
      </axis>
   	</joint>

   	<joint name="prop3_joint" type="revolute">
      <parent>base_frame</parent>
      <child>prop3</child>
      <pose>0 0 0  0 0 0</pose>
      <axis>
        <xyz>0 0 1</xyz>
      </axis>
   	</joint>

   	<joint name="prop4_joint" type="revolute">
      <parent>base_frame</parent>
      <child>prop4</child>
      <pose>0 0 0  0 0 0</pose>
      <axis>
        <xyz>0 0 -1</xyz>
      </axis>
   	</joint>



<!-- ****************************** Plugins *********************************** -->

  <plugin name="set_speed_joint_plugin" filename="libset_speed_joint_plugin.so">
     <namespace_model>qball</namespace_model>
     <activate_pid_control>yes</activate_pid_control>                
     <prop_kp>0.1</prop_kp>
     <prop_ki>0.0</prop_ki>
     <prop_kd>0.0</prop_kd>
  </plugin>    

  </model>
</sdf>
